Workbook
Name Slicer_Year: #N/A

Sheet SOFP
A2: Year | B2: 17 | C2: =B2+1 -> 18 | D2: =C2+1 -> 19 | E2: =D2+1 -> 20 | F2: =E2+1 -> 21 | G2: =F2+1 -> 22 | H2: =G2+1 -> 23 | I2: =H2+1 -> 24 | J2: =I2+1 -> 25
A4: Total Non-Current Assets | B4: 12947.3 | C4: 14647.53 | D4: 14981.76 | E4: 19933.66 | F4: 24308.45 | G4: 24502.75 | H4: 25034.49 | I4: 30692.9 | J4: 39196.85
A5: Inventories | B5: 34057.07 | C5: 39729.55 | D5: 35585.37 | E5: 36357.36 | F5: 43881.32 | G5: 47456.5 | H5: 57138.65 | I5: 67404.21 | J5: 75677.94
A6: Other Current Assets | B6: =B7-B5 -> 8143.76 | C6: =C7-C5 -> 12067.65 | D6: =D7-D5 -> 9874.04 | E6: =E7-E5 -> 10782.72 | F6: =F7-F5 -> 10934.58 | G6: =G7-G5 -> 5600 | H6: =H7-H5 -> 8464.49 | I6: =I7-I5 -> 9846.65 | J6: =J7-J5 -> 12217.52
A7: Total Current Assets | B7: 42200.83 | C7: 51797.2 | D7: 45459.41 | E7: 47140.08 | F7: 54815.9 | G7: 53056.5 | H7: 65603.14 | I7: 77250.86 | J7: 87895.46
A8: Total Assets | B8: =B4+B7 -> 55148.13 | C8: =C4+C7 -> 66444.73 | D8: =D4+D7 -> 60441.17 | E8: =E4+E7 -> 67073.74 | F8: =F4+F7 -> 79124.35 | G8: =G4+G7 -> 77559.25 | H8: =H4+H7+1339.1 -> 91976.73 | I8: =I4+I7+1339.1 -> 109282.86 | J8: =J4+J7 -> 127092.31
A10: Total equity | B10: 14808.8 | C10: 20802.98 | D10: 21254.34 | E10: 21573.7 | F10: 30254.48 | G10: 32635.57 | H10: 36666.22 | I10: 41669.5 | J10: 47772.58
A11: Non-Current Liabilities
A12: Financial Liabilities
A13: Borrowings | B13: 2618.95 | C13: 1647.85 | D13: 799.28 | E13: 375.07 | F13: 161.54 | G13: 0 | H13: 0 | I13: 0 | J13: 0
A14: Lease Liabilities | B14: 0 | C14: 0 | D14: 0 | E14: 6484.63 | F14: 6044.09 | G14: 5481.54 | H14: 6315.94 | I14: 9370.45 | J14: 12235.48
A15: Total Non-Current Liabilities | B15: 2699.61 | C15: 1875.46 | D15: 1115.66 | E15: 7098.28 | F15: 6481.93 | G15: 5751.76 | H15: 6601.59 | I15: 9709.39 | J15: 12918.32
A16: Total Current Liabilities | B16: 37639.72 | C16: 43766.29 | D16: 38071.17 | E16: 38401.76 | F16: 42387.94 | G16: 39171.92 | H16: 48708.92 | I16: 57903.97 | J16: 66401.41
A17: Total Equity + Liabilities | B17: =B10+B15+B16 -> 55148.13 | C17: =C10+C15+C16 -> 66444.73 | D17: =D10+D15+D16 -> 60441.17 | E17: =E10+E15+E16 -> 67073.74 | F17: =F10+F15+F16 -> 79124.35 | G17: =G10+G15+G16 -> 77559.25 | H17: =H10+H15+H16 -> 91976.73 | I17: =I10+I15+I16 -> 109282.86 | J17: =J10+J15+J16 -> 127092.31
A21: Current Ratio | B21: =B7/B16 -> 1.1211781 | C21: =C7/C16 -> 1.1834953 | D21: =D7/D16 -> 1.1940639 | E21: =E7/E16 -> 1.22755 | F21: =F7/F16 -> 1.2931957 | G21: =G7/G16 -> 1.3544524 | H21: =H7/H16 -> 1.3468404 | I21: =I7/I16 -> 1.3341203 | J21: =J7/J16 -> 1.3236987
A22: Quick Ratio | B22: =(B7-B5)/B16 -> 0.2163608 | C22: =(C7-C5)/C16 -> 0.27572933 | D22: =(D7-D5)/D16 -> 0.25935741 | E22: =(E7-E5)/E16 -> 0.28078713 | F22: =(F7-F5)/F16 -> 0.25796441 | G22: =(G7-G5)/G16 -> 0.14295955 | H22: =(H7-H5)/H16 -> 0.173777 | I22: =(I7-I5)/I16 -> 0.17005138 | J22: =(J7-J5)/J16 -> 0.18399489
A23: Gearing Ratio (D/E) | B23: =(B13+B14)/B10 -> 0.17685093 | C23: =(C13+C14)/C10 -> 0.079212209 | D23: =(D13+D14)/D10 -> 0.037605496 | E23: =(E13+E14)/E10 -> 0.31796586 | F23: =(F13+F14)/F10 -> 0.20511442 | G23: =(G13+G14)/G10 -> 0.16796213 | H23: =(H13+H14)/H10 -> 0.17225501 | I23: =(I13+I14)/I10 -> 0.22487551 | J23: =(J13+J14)/J10 -> 0.25611931
A27: Inventory | B27: =B5 -> 34057.07 | C27: =C5 -> 39729.55 | D27: =D5 -> 35585.37 | E27: =E5 -> 36357.36 | F27: =F5 -> 43881.32 | G27: =G5 -> 47456.5 | H27: =H5 -> 57138.65 | I27: =I5 -> 67404.21 | J27: =J5 -> 75677.94
A28: TR | B28: 58.36 | C28: 7.26 | D28: 50.32 | E28: 20.72 | F28: 39.91 | G28: 44.63 | H28: 1075.66 | I28: 1697.32 | J28: 3313.18
A29: TP | B29: 6800.99 | C29: 19198.5 | D29: 2843.38 | E29: 2992.19 | F29: 5580.51 | G29: 4952.55 | H29: 9684.98 | I29: 15340.29 | J29: =4.67+18681.03 -> 18685.7
A30: Cost Of Materials Consumed | B30: 66719.77 | C30: 74188.17 | D30: 57096.64 | E30: 64922.72 | F30: 66073.64 | G30: 81465.3 | H30: 108186.3 | I30: 145114.81 | J30: 191696.48
A32: Inventory days | B32: =B27*365/SOPL!B5 -> 202.06188 | C32: =C27/SOPL!C5*365 -> 209.32339 | D32: =D27/SOPL!D5*365 -> 208.77951 | E32: =E27/SOPL!E5*365 -> 205.58765 | F32: =F27/SOPL!F5*365 -> 263.2528 | G32: =G27/SOPL!G5*365 -> 225.85801 | H32: =H27/SOPL!H5*365 -> 213.37803 | I32: =I27/SOPL!I5*365 -> 182.35622 | J32: =J27/SOPL!J5*365 -> 146.29407
A33: TR days | B33: =B28*365/SOPL!B4 -> 0.28419794 | C33: =C28*365/SOPL!C4 -> 0.032106212 | D33: =D28*365/SOPL!D4 -> 0.24659493 | E33: =E28*365/SOPL!E4 -> 0.096392655 | F33: =F28*365/SOPL!F4 -> 0.19885512 | G33: =G28*365/SOPL!G4 -> 0.17987846 | H33: =H28*365/SOPL!H4 -> 3.3892877 | I33: =I28*365/SOPL!I4 -> 3.9253561 | J33: =J28*365/SOPL!J4 -> 5.5886748
A34: TP days | B34: =B29*365/B30 -> 37.205784 | C34: =C29*365/C30 -> 94.45512 | D34: =D29*365/D30 -> 18.176791 | E34: =E29*365/E30 -> 16.822298 | F34: =F29*365/F30 -> 30.827515 | G34: =G29*365/G30 -> 22.189579 | H34: =H29*365/H30 -> 32.675281 | I34: =I29*365/I30 -> 38.584662 | J34: =J29*365/J30 -> 35.578538
A35: Working Capital Cycle | B35: =B32+B33-B34 -> 165.14029 | C35: =C32+C33-C34 -> 114.90037 | D35: =D32+D33-D34 -> 190.84932 | E35: =E32+E33-E34 -> 188.86175 | F35: =F32+F33-F34 -> 232.62414 | G35: =G32+G33-G34 -> 203.84831 | H35: =H32+H33-H34 -> 184.09204 | I35: =I32+I33-I34 -> 147.69692 | J35: =J32+J33-J34 -> 116.3042
A40: Year | C40: Total Non-Current Assets | D40: Inventories | E40: Other Current Assets | F40: Total Current Assets | G40: Total Assets | I40: Total equity | J40: Non-Current Liabilities | K40: Financial Liabilities | L40: Borrowings | M40: Lease Liabilities | N40: Total Non-Current Liabilities | O40: Total Current Liabilities | P40: Total Equity + Liabilities
A41: 17 | C41: 12947.3 | D41: 34057.07 | E41: =F41-D41 -> 8143.76 | F41: 42200.83 | G41: =C41+F41 -> 55148.13 | I41: 14808.8 | L41: 2618.95 | M41: 0 | N41: 2699.61 | O41: 37639.72 | P41: =I41+N41+O41 -> 55148.13
A42: =A41+1 -> 18 | C42: 14647.53 | D42: 39729.55 | E42: =F42-D42 -> 12067.65 | F42: 51797.2 | G42: =C42+F42 -> 66444.73 | I42: 20802.98 | L42: 1647.85 | M42: 0 | N42: 1875.46 | O42: 43766.29 | P42: =I42+N42+O42 -> 66444.73
A43: =A42+1 -> 19 | C43: 14981.76 | D43: 35585.37 | E43: =F43-D43 -> 9874.04 | F43: 45459.41 | G43: =C43+F43 -> 60441.17 | I43: 21254.34 | L43: 799.28 | M43: 0 | N43: 1115.66 | O43: 38071.17 | P43: =I43+N43+O43 -> 60441.17
A44: =A43+1 -> 20 | C44: 19933.66 | D44: 36357.36 | E44: =F44-D44 -> 10782.72 | F44: 47140.08 | G44: =C44+F44 -> 67073.74 | I44: 21573.7 | L44: 375.07 | M44: 6484.63 | N44: 7098.28 | O44: 38401.76 | P44: =I44+N44+O44 -> 67073.74
A45: =A44+1 -> 21 | C45: 24308.45 | D45: 43881.32 | E45: =F45-D45 -> 10934.58 | F45: 54815.9 | G45: =C45+F45 -> 79124.35 | I45: 30254.48 | L45: 161.54 | M45: 6044.09 | N45: 6481.93 | O45: 42387.94 | P45: =I45+N45+O45 -> 79124.35
A46: =A45+1 -> 22 | C46: 24502.75 | D46: 47456.5 | E46: =F46-D46 -> 5600 | F46: 53056.5 | G46: =C46+F46 -> 77559.25 | I46: 32635.57 | L46: 0 | M46: 5481.54 | N46: 5751.76 | O46: 39171.92 | P46: =I46+N46+O46 -> 77559.25
A47: =A46+1 -> 23 | C47: 25034.49 | D47: 57138.65 | E47: =F47-D47 -> 8464.49 | F47: 65603.14 | G47: =C47+F47+1339.1 -> 91976.73 | I47: 36666.22 | L47: 0 | M47: 6315.94 | N47: 6601.59 | O47: 48708.92 | P47: =I47+N47+O47 -> 91976.73
A48: =A47+1 -> 24 | C48: 30692.9 | D48: 67404.21 | E48: =F48-D48 -> 9846.65 | F48: 77250.86 | G48: =C48+F48+1339.1 -> 109282.86 | I48: 41669.5 | L48: 0 | M48: 9370.45 | N48: 9709.39 | O48: 57903.97 | P48: =I48+N48+O48 -> 109282.86
A49: =A48+1 -> 25 | C49: 39196.85 | D49: 75677.94 | E49: =F49-D49 -> 12217.52 | F49: 87895.46 | G49: =C49+F49 -> 127092.31 | I49: 47772.58 | L49: 0 | M49: 12235.48 | N49: 12918.32 | O49: 66401.41 | P49: =I49+N49+O49 -> 127092.31

Sheet SOPL
A1: in ₹ million
A2: =SOFP!A2 -> Year | B2: =SOFP!B2 -> 17 | C2: =SOFP!C2 -> 18 | D2: =SOFP!D2 -> 19 | E2: =SOFP!E2 -> 20 | F2: =SOFP!F2 -> 21 | G2: =SOFP!G2 -> 22 | H2: =SOFP!H2 -> 23 | ... J2: =SOFP!J2 -> 25
A4: Revenue | B4: =75552.29-599.6 -> 74952.69 | C4: =82754.75-219.32 -> 82535.43 | D4: 74481.66 | E4: 78458.26 | F4: 73255.09 | G4: 90560.87 | H4: 115840.24 | I4: 157825.63 | J4: 216385.95
A5: COGS | B5: =66719.77-5199.85 -> 61519.92 | C5: =74188.17-4911.22 -> 69276.95 | D5: =57096.64+5115.69 -> 62212.33 | E5: =64922.72-373.92 -> 64548.8 | F5: =66073.64-5232.19 -> 60841.45 | G5: =81465.3-4772.77 -> 76692.53 | H5: =108186.3-10446.12 -> 97740.18 | I5: =145114.81-10200.1 -> 134914.71 | J5: =191696.48-2881.93 -> 188814.55
A6: GP | B6: =B4-B5 -> 13432.77 | C6: =C4-C5 -> 13258.48 | D6: =D4-D5 -> 12269.33 | E6: =E4-E5 -> 13909.46 | F6: =F4-F5 -> 12413.64 | G6: =G4-G5 -> 13868.34 | H6: =H4-H5 -> 18100.06 | I6: =I4-I5 -> 22910.92 | J6: =J4-J5 -> 27571.4
A7: Other Income | B7: 513.17 | C7: 435.38 | D7: 584.16 | E7: 982.96 | F7: 528.68 | G7: 424.49 | H7: 426.35 | I7: 764.77 | J7: 1485.46
A8: Operating Expenses | B8: =2558.18 -> 2558.18 | C8: 3026.59 | D8: 3190.17 | E8: 3000.7 | F8: 2868.3 | G8: 2973.64 | H8: 3711.55 | I8: 5183.37 | J8: 6386.72
A9: Other Exp | B9: 6085.21 | C9: 5316.53 | D9: 5835.11 | E9: 4547.44 | F9: 3298.26 | G9: 3979.35 | H9: 5057.72 | I9: 6570.74 | J9: 8389.23
A10: EBITDA | B10: =B6+B7-B8-B9 -> 5302.55 | C10: =C6+C7-C8-C9 -> 5350.74 | D10: =D6+D7-D8-D9 -> 3828.21 | E10: =E6+E7-E8-E9 -> 7344.28 | F10: =F6+F7-F8-F9 -> 6775.76 | G10: =G6+G7-G8-G9 -> 7339.84 | H10: =H6+H7-H8-H9 -> 9757.14 | I10: =I6+I7-I8-I9 -> 11921.58 | J10: =J6+J7-J8-J9 -> 14280.91
A11: D&A | B11: 775.4 | C11: 818.21 | D11: 906.25 | E11: 1859.75 | F11: 1740.23 | G11: 1805.23 | H11: 1830.62 | I11: 2063.85 | J11: 2461.45
A12: EBIT | B12: =B10-B11 -> 4527.15 | C12: =C10-C11 -> 4532.53 | D12: =D10-D11 -> 2921.96 | E12: =E10-E11 -> 5484.53 | F12: =F10-F11 -> 5035.53 | G12: =G10-G11 -> 5534.61 | H12: =H10-H11 -> 7926.52 | I12: =I10-I11 -> 9857.73 | J12: =J10-J11 -> 11819.46
A13: Finance Cost | B13: 3138.15 | C13: 2337.11 | D13: 2277.6 | E13: 3131.27 | F13: 3160.68 | G13: 2636.04 | H13: 2343.19 | I13: 2416.52 | J13: 2496.81
A14: EBT | B14: =B12-B13 -> 1389 | C14: =C12-C13 -> 2195.42 | D14: =D12-D13 -> 644.36 | E14: =E12-E13 -> 2353.26 | F14: =F12-F13 -> 1874.85 | G14: =G12-G13 -> 2898.57 | H14: =H12-H13 -> 5583.33 | I14: =I12-I13 -> 7441.21 | J14: =J12-J13 -> 9322.65
A15: Tax | B15: 244.18 | C15: 819.52 | D15: 195.02 | E15: 789.75 | F15: 492.53 | G15: 756.85 | H15: 1352.71 | I15: 1900.63 | J15: 2435.83
A16: PAT | B16: =B14-B15 -> 1144.82 | C16: =C14-C15 -> 1375.9 | D16: =D14-D15 -> 449.34 | E16: =E14-E15 -> 1563.51 | F16: =F14-F15 -> 1382.32 | G16: =G14-G15 -> 2141.72 | H16: =H14-H15-332.51 -> 3898.11 | I16: =I14-I15 -> 5540.58 | J16: =J14-J15 -> 6886.82
A17: EPS (Basic) (₹/share) | B17: 1.36 | C17: 1.64 | D17: 0.54 | E17: 1.86 | F17: 1.63 | G17: 2.08 | H17: 3.78 | I17: 5.38 | J17: 6.68
A20: Revenue Growth % | B20: 0 | C20: =C4/B4-1 -> 0.10116702 | D20: =D4/C4-1 -> -0.097579549 | E20: =E4/D4-1 -> 0.053390325 | F20: =F4/E4-1 -> -0.066317683 | G20: =G4/F4-1 -> 0.23623997 | H20: =H4/G4-1 -> 0.27914231 | I20: =I4/H4-1 -> 0.36244219 | J20: =J4/I4-1 -> 0.37104442
A21: Interest Cover | B21: =B12/B13 -> 1.4426175 | C21: =C12/C13 -> 1.9393738 | D21: =D12/D13 -> 1.2829118 | E21: =E12/E13 -> 1.7515353 | F21: =F12/F13 -> 1.5931793 | G21: =G12/G13 -> 2.0995926 | H21: =H12/H13 -> 3.3827901 | I21: =I12/I13 -> 4.0793083 | J21: =J12/J13 -> 4.7338244
A22: Gross Profit Margin % | B22: =B6/B4 -> 0.17921665 | C22: =C6/C4 -> 0.16063986 | D22: =D6/D4 -> 0.16472955 | E22: =E6/E4 -> 0.17728484 | F22: =F6/F4 -> 0.16945771 | G22: =G6/G4 -> 0.15313833 | H22: =H6/H4 -> 0.15625019 | I22: =I6/I4 -> 0.14516603 | J22: =J6/J4 -> 0.1274177
A23: EBITDA Margin % | B23: =B10/B4 -> 0.070745293 | C23: =C10/C4 -> 0.064829613 | D23: =D10/D4 -> 0.051398022 | E23: =E10/E4 -> 0.09360748 | F23: =F10/F4 -> 0.092495416 | G23: =G10/G4 -> 0.081048691 | H23: =H10/H4 -> 0.08422928 | I23: =I10/I4 -> 0.075536401 | J23: =J10/J4 -> 0.0659974
A24: EBIT Margin % | B24: =B12/B4 -> 0.0604001 | C24: =C12/C4 -> 0.054916174 | D24: =D12/D4 -> 0.039230597 | E24: =E12/E4 -> 0.069903793 | F24: =F12/F4 -> 0.06873966 | G24: =G12/G4 -> 0.061114806 | H24: =H12/H4 -> 0.068426309 | I24: =I12/I4 -> 0.062459627 | J24: =J12/J4 -> 0.054622123
A25: PAT Margin % | B25: =B16/B4 -> 0.015273901 | C25: =C16/C4 -> 0.016670417 | D25: =D16/D4 -> 0.0060328945 | E25: =E16/E4 -> 0.019927921 | F25: =F16/F4 -> 0.018869952 | G25: =G16/G4 -> 0.023649508 | H25: =H16/H4 -> 0.033650742 | I25: =I16/I4 -> 0.035105705 | J25: =J16/J4 -> 0.031826558
A26: EPS Growth % | B26: 0 | C26: =C17/B17-1 -> 0.20588235 | D26: =D17/C17-1 -> -0.67073171 | E26: =E17/D17-1 -> 2.4444444 | F26: =F17/E17-1 -> -0.12365591 | G26: =G17/F17-1 -> 0.27607362 | H26: =H17/G17-1 -> 0.81730769 | I26: =I17/H17-1 -> 0.42328042 | J26: =J17/I17-1 -> 0.24163569
A30: Year | B30: Revenue | C30: Gross Profit | D30: EBITDA | E30: EBIT | F30: EBT | G30: PAT | H30: EPS (Basic) (₹/share) | J30: Year | K30: Revenue | L30: Gross profit | M30: EBITDA | N30: EBIT | O30: EBT | P30: PAT | Q30: EPS (Basic) (₹/share) | R30: Revenue Growth | S30: Interest Cover | T30: Gross Profit Margin % | U30: EBITDA Margin % | V30: EBIT Margin % | W30: EBT Margin % | X30: PAT Margin % | Y30: EPS Growth % | Z30: CFO | AA30: CFI | AB30: CFF | AC30: Current Ratio | AD30: Quick Ratio | AE30: Gearing Ratio (D/E) | AF30: Working Capital Cycle | AG30: GP GROWTH | AH30: EBITDA GROWTH | AI30: EBIT GROWTH | AJ30: EBT GROWTH | AK30: PAT GROWTH | AL30: ROCE % | AM30: ROE %
A31: 17 | B31: =75552.29-599.6 -> 74952.69 | C31: 13432.77 | D31: 5302.55 | E31: 4527.15 | F31: 1389 | G31: 1144.82 | H31: 1.36 | J31: =SOPL!$A31 -> 17 | K31: =B31 -> 74952.69 | L31: =C31 -> 13432.77 | M31: =D31 -> 5302.55 | N31: =E31 -> 4527.15 | O31: =F31 -> 1389 | P31: =G31 -> 1144.82 | Q31: =H31 -> 1.36 | R31: 0 | S31: =C44 -> 1.4426175 | T31: =L31/$K31 -> 0.17921665 | U31: =M31/$K31 -> 0.070745293 | V31: =N31/$K31 -> 0.0604001 | W31: =O31/$K31 -> 0.01853169 | X31: =P31/$K31 -> 0.015273901 | Y31: 0 | Z31: 498.64 | AA31: -1150.55 | AB31: 702.56 | AC31: =SOFP!B21 -> 1.1211781 | AD31: =SOFP!B22 -> 0.2163608 | AE31: =SOFP!B23 -> 0.17685093 | AF31: =SOFP!B32+SOFP!B33-SOFP!B34 -> 165.14029 | AG31: 0 | AH31: 0 | AI31: 0 | AJ31: 0 | AK31: 0 | AL31: =SOPL!N31/(SOFP!G41-SOFP!O41) -> 0.25857002 | AM31: =SOPL!O31/SOFP!I41 -> 0.093795581
A32: =A31+1 -> 18 | B32: =82754.75-219.32 -> 82535.43 | C32: 13258.48 | D32: 5350.74 | E32: 4532.53 | F32: 2195.42 | G32: 1375.9 | H32: 1.64 | J32: =SOPL!$A32 -> 18 | K32: =B32 -> 82535.43 | L32: =C32 -> 13258.48 | M32: =D32 -> 5350.74 | N32: =E32 -> 4532.53 | O32: =F32 -> 2195.42 | P32: =G32 -> 1375.9 | Q32: =H32 -> 1.64 | R32: =K32/K31-1 -> 0.10116702 | S32: =C45 -> 1.9393738 | T32: =L32/$K32 -> 0.16063986 | U32: =M32/$K32 -> 0.064829613 | V32: =N32/$K32 -> 0.054916174 | W32: =O32/$K32 -> 0.026599728 | X32: =P32/$K32 -> 0.016670417 | Y32: =Q32/Q31-1 -> 0.20588235 | Z32: 9690.59 | AA32: -2979.84 | AB32: -6194.19 | AC32: =SOFP!C21 -> 1.1834953 | AD32: =SOFP!C22 -> 0.27572933 | AE32: =SOFP!C23 -> 0.079212209 | AF32: =SOFP!C35 -> 114.90037 | AG32: =L32/L31-1 -> -0.012974986 | AH32: =M32/M31-1 -> 0.0090880803 | AI32: =N32/N31-1 -> 0.0011883856 | AJ32: =O32/O31-1 -> 0.58057595 | AK32: =P32/P31-1 -> 0.20184833 | AL32: =SOPL!N32/(SOFP!G42-SOFP!O42) -> 0.19986075 | AM32: =SOPL!O32/SOFP!I42 -> 0.10553392
A33: =A32+1 -> 19 | B33: 74481.66 | C33: 12269.33 | D33: 3828.21 | E33: 2921.96 | F33: 644.36 | G33: 449.34 | H33: 0.54 | J33: =SOPL!$A33 -> 19 | K33: =B33 -> 74481.66 | L33: =C33 -> 12269.33 | M33: =D33 -> 3828.21 | N33: =E33 -> 2921.96 | O33: =F33 -> 644.36 | P33: =G33 -> 449.34 | Q33: =H33 -> 0.54 | R33: =K33/K32-1 -> -0.097579549 | S33: =C46 -> 1.2829118 | T33: =L33/$K33 -> 0.16472955 | U33: =M33/$K33 -> 0.051398022 | V33: =N33/$K33 -> 0.039230597 | W33: =O33/$K33 -> 0.0086512572 | X33: =P33/$K33 -> 0.0060328945 | Y33: =Q33/Q32-1 -> -0.67073171 | Z33: -263.39 | AA33: 1434.64 | AB33: -1418.2 | AC33: =SOFP!D21 -> 1.1940639 | AD33: =SOFP!D22 -> 0.25935741 | AE33: =SOFP!D23 -> 0.037605496 | AF33: =SOFP!D35 -> 190.84932 | AG33: =L33/L32-1 -> -0.074605083 | AH33: =M33/M32-1 -> -0.28454569 | AI33: =N33/N32-1 -> -0.35533576 | AJ33: =O33/O32-1 -> -0.70649807 | AK33: =P33/P32-1 -> -0.67342103 | AL33: =SOPL!N33/(SOFP!G43-SOFP!O43) -> 0.13061958 | AM33: =SOPL!O33/SOFP!I43 -> 0.030316632
A34: =A33+1 -> 20 | B34: 78458.26 | C34: 13909.46 | D34: 7344.28 | E34: 5484.53 | F34: 2353.26 | G34: 1563.51 | H34: 1.86 | J34: =SOPL!$A34 -> 20 | K34: =B34 -> 78458.26 | L34: =C34 -> 13909.46 | M34: =D34 -> 7344.28 | N34: =E34 -> 5484.53 | O34: =F34 -> 2353.26 | P34: =G34 -> 1563.51 | Q34: =H34 -> 1.86 | R34: =K34/K33-1 -> 0.053390325 | S34: =C47 -> 1.7515353 | T34: =L34/$K34 -> 0.17728484 | U34: =M34/$K34 -> 0.09360748 | V34: =N34/$K34 -> 0.069903793 | W34: =O34/$K34 -> 0.029993783 | X34: =P34/$K34 -> 0.019927921 | Y34: =Q34/Q33-1 -> 2.4444444 | Z34: 1561.58 | AA34: 38.63 | AB34: -1257.67 | AC34: =SOFP!E21 -> 1.22755 | AD34: =SOFP!E22 -> 0.28078713 | AE34: =SOFP!E23 -> 0.31796586 | AF34: =SOFP!E35 -> 188.86175 | AG34: =L34/L33-1 -> 0.13367723 | AH34: =M34/M33-1 -> 0.9184632 | AI34: =N34/N33-1 -> 0.87700379 | AJ34: =O34/O33-1 -> 2.6520889 | AK34: =P34/P33-1 -> 2.47957 | AL34: =SOPL!N34/(SOFP!G44-SOFP!O44) -> 0.19128536 | AM34: =SOPL!O34/SOFP!I44 -> 0.10908004
A35: =A34+1 -> 21 | B35: 73255.09 | C35: 12413.64 | D35: 6775.76 | E35: 5035.53 | F35: 1874.85 | G35: 1382.32 | H35: 1.63 | J35: =SOPL!$A35 -> 21 | K35: =B35 -> 73255.09 | L35: =C35 -> 12413.64 | M35: =D35 -> 6775.76 | N35: =E35 -> 5035.53 | O35: =F35 -> 1874.85 | P35: =G35 -> 1382.32 | Q35: =H35 -> 1.63 | R35: =K35/K34-1 -> -0.066317683 | S35: =C48 -> 1.5931793 | T35: =L35/$K35 -> 0.16945771 | U35: =M35/$K35 -> 0.092495416 | V35: =N35/$K35 -> 0.06873966 | W35: =O35/$K35 -> 0.025593443 | X35: =P35/$K35 -> 0.018869952 | Y35: =Q35/Q34-1 -> -0.12365591 | Z35: 5159.14 | AA35: -3099.35 | AB35: -225.07 | AC35: =SOFP!F21 -> 1.2931957 | AD35: =SOFP!F22 -> 0.25796441 | AE35: =SOFP!F23 -> 0.20511442 | AF35: =SOFP!F35 -> 232.62414 | AG35: =L35/L34-1 -> -0.10753976 | AH35: =M35/M34-1 -> -0.077409903 | AI35: =N35/N34-1 -> -0.081866632 | AJ35: =O35/O34-1 -> -0.2032967 | AK35: =P35/P34-1 -> -0.11588669 | AL35: =SOPL!N35/(SOFP!G45-SOFP!O45) -> 0.13707191 | AM35: =SOPL!O35/SOFP!I45 -> 0.061969335
A36: =A35+1 -> 22 | B36: 90560.87 | C36: 13868.34 | D36: 7339.84 | E36: 5534.61 | F36: 2898.57 | G36: 2141.72 | H36: 2.08 | J36: =SOPL!$A36 -> 22 | K36: =B36 -> 90560.87 | L36: =C36 -> 13868.34 | M36: =D36 -> 7339.84 | N36: =E36 -> 5534.61 | O36: =F36 -> 2898.57 | P36: =G36 -> 2141.72 | Q36: =H36 -> 2.08 | R36: =K36/K35-1 -> 0.23623997 | S36: =C49 -> 2.0995926 | T36: =L36/$K36 -> 0.15313833 | U36: =M36/$K36 -> 0.081048691 | V36: =N36/$K36 -> 0.061114806 | W36: =O36/$K36 -> 0.03200687 | X36: =P36/$K36 -> 0.023649508 | Y36: =Q36/Q35-1 -> 0.27607362 | Z36: 1086.08 | AA36: 1439.7 | AB36: -4737.48 | AC36: =SOFP!G21 -> 1.3544524 | AD36: =SOFP!G22 -> 0.14295955 | AE36: =SOFP!G23 -> 0.16796213 | AF36: =SOFP!G35 -> 203.84831 | AG36: =L36/L35-1 -> 0.11718561 | AH36: =M36/M35-1 -> 0.083249702 | AI36: =N36/N35-1 -> 0.099111712 | AJ36: =O36/O35-1 -> 0.54602768 | AK36: =P36/P35-1 -> 0.54936628 | AL36: =SOPL!N36/(SOFP!G46-SOFP!O46) -> 0.14417804 | AM36: =SOPL!O36/SOFP!I46 -> 0.088816282
A37: =A36+1 -> 23 | B37: 115840.24 | C37: 18100.06 | D37: 9757.14 | E37: 7926.52 | F37: 5583.33 | G37: 3898.11 | H37: 3.78 | J37: =SOPL!$A37 -> 23 | K37: =B37 -> 115840.24 | L37: =C37 -> 18100.06 | M37: =D37 -> 9757.14 | N37: =E37 -> 7926.52 | O37: =F37 -> 5583.33 | P37: =G37 -> 3898.11 | Q37: =H37 -> 3.78 | R37: =K37/K36-1 -> 0.27914231 | S37: =C50 -> 3.3827901 | T37: =L37/$K37 -> 0.15625019 | U37: =M37/$K37 -> 0.08422928 | V37: =N37/$K37 -> 0.068426309 | W37: =O37/$K37 -> 0.048198536 | X37: =P37/$K37 -> 0.033650742 | Y37: =Q37/Q36-1 -> 0.81730769 | Z37: 7145.97 | AA37: -3617.53 | AB37: -3758.46 | AC37: =SOFP!H21 -> 1.3468404 | AD37: =SOFP!H22 -> 0.173777 | AE37: =SOFP!H23 -> 0.17225501 | AF37: =SOFP!H35 -> 184.09204 | AG37: =L37/L36-1 -> 0.30513529 | AH37: =M37/M36-1 -> 0.3293396 | AI37: =N37/N36-1 -> 0.43217318 | AJ37: =O37/O36-1 -> 0.92623604 | AK37: =P37/P36-1 -> 0.82008386 | AL37: =SOPL!N37/(SOFP!G47-SOFP!O47) -> 0.1831967 | AM37: =SOPL!O37/SOFP!I47 -> 0.15227449
A38: =A37+1 -> 24 | B38: 157825.63 | C38: 22910.92 | D38: 11921.58 | E38: 9857.73 | F38: 7441.21 | G38: 5540.58 | H38: 5.38 | J38: =SOPL!$A38 -> 24 | K38: =B38 -> 157825.63 | L38: =C38 -> 22910.92 | M38: =D38 -> 11921.58 | N38: =E38 -> 9857.73 | O38: =F38 -> 7441.21 | P38: =G38 -> 5540.58 | Q38: =H38 -> 5.38 | R38: =K38/K37-1 -> 0.36244219 | S38: =C51 -> 4.0793083 | T38: =L38/$K38 -> 0.14516603 | U38: =M38/$K38 -> 0.075536401 | V38: =N38/$K38 -> 0.062459627 | W38: =O38/$K38 -> 0.047148299 | X38: =P38/$K38 -> 0.035105705 | Y38: =Q38/Q37-1 -> 0.42328042 | Z38: 9855.63 | AA38: -1163.62 | AB38: -8327.49 | AC38: =SOFP!I21 -> 1.3341203 | AD38: =SOFP!I22 -> 0.17005138 | AE38: =SOFP!I23 -> 0.22487551 | AF38: =SOFP!I35 -> 147.69692 | AG38: =L38/L37-1 -> 0.26579249 | AH38: =M38/M37-1 -> 0.2218314 | AI38: =N38/N37-1 -> 0.24363907 | AJ38: =O38/O37-1 -> 0.33275483 | AK38: =P38/P37-1 -> 0.42135035 | AL38: =SOPL!N38/(SOFP!G48-SOFP!O48) -> 0.19186343 | AM38: =SOPL!O38/SOFP!I48 -> 0.1785769
A39: =A38+1 -> 25 | B39: 216385.95 | C39: 27571.4 | D39: 14280.91 | E39: 11819.46 | F39: 9322.65 | G39: 6886.82 | H39: 6.68 | J39: =SOPL!$A39 -> 25 | K39: =B39 -> 216385.95 | L39: =C39 -> 27571.4 | M39: =D39 -> 14280.91 | N39: =E39 -> 11819.46 | O39: =F39 -> 9322.65 | P39: =G39 -> 6886.82 | Q39: =H39 -> 6.68 | R39: =K39/K38-1 -> 0.37104442 | S39: =C52 -> 4.7338244 | T39: =L39/$K39 -> 0.1274177 | U39: =M39/$K39 -> 0.0659974 | V39: =N39/$K39 -> 0.054622123 | W39: =O39/$K39 -> 0.043083435 | X39: =P39/$K39 -> 0.031826558 | Y39: =Q39/Q38-1 -> 0.24163569 | Z39: 9732.96 | AA39: -2931.5 | AB39: -5130.11 | AC39: =SOFP!J21 -> 1.3236987 | AD39: =SOFP!J22 -> 0.18399489 | AE39: =SOFP!J23 -> 0.25611931 | AF39: =SOFP!J35 -> 116.3042 | AG39: =L39/L38-1 -> 0.20341741 | AH39: =M39/M38-1 -> 0.19790414 | AI39: =N39/N38-1 -> 0.19900423 | AJ39: =O39/O38-1 -> 0.2528406 | AK39: =P39/P38-1 -> 0.24297817 | AL39: =SOPL!N39/(SOFP!G49-SOFP!O49) -> 0.19474847 | AM39: =SOPL!O39/SOFP!I49 -> 0.19514646
A41: CAGR (5Y) | B41: =(B39/B34)^(1/5)-1 -> 0.2249492 | C41: =(C39/C34)^(1/5)-1 -> 0.14664692 | D41: =(D39/D34)^(1/5)-1 -> 0.14225043 | E41: =(E39/E34)^(1/5)-1 -> 0.16598146 | F41: =(F39/F34)^(1/5)-1 -> 0.31696397 | G41: =(G39/G34)^(1/5)-1 -> 0.34518995 | H41: =(H39/H34)^(1/5)-1 -> 0.29137598
A42: CAGR (3Y) | B42: =(B39/B36)^(1/3)-1 -> 0.33689149 | C42: =(C39/C36)^(1/3)-1 -> 0.25741348 | D42: =(D39/D36)^(1/3)-1 -> 0.24840767 | E42: =(E39/E36)^(1/3)-1 -> 0.28776575 | F42: =(F39/F36)^(1/3)-1 -> 0.47610934 | G42: =(G39/G36)^(1/3)-1 -> 0.47599656 | H42: =(H39/H36)^(1/3)-1 -> 0.47538164
A43: Year | B43: Revenue Growth % | C43: Interest Cover | D43: Gross Profit Margin % | E43: EBITDA Margin % | F43: EBIT Margin % | G43: PAT Margin % | H43: EPS Growth %
A44: 17 | B44: =B20 -> 0 | C44: =B21 -> 1.4426175 | D44: =B22 -> 0.17921665 | E44: =B23 -> 0.070745293 | F44: =B24 -> 0.0604001 | G44: =B25 -> 0.015273901 | H44: 0
A45: =A44+1 -> 18 | B45: =C20 -> 0.10116702 | C45: =C21 -> 1.9393738 | D45: =C22 -> 0.16063986 | E45: =C23 -> 0.064829613 | F45: =C24 -> 0.054916174 | G45: =C25 -> 0.016670417 | H45: =H32/H31-1 -> 0.20588235
A46: =A45+1 -> 19 | B46: =D20 -> -0.097579549 | C46: =D21 -> 1.2829118 | D46: =D22 -> 0.16472955 | E46: =D23 -> 0.051398022 | F46: =D24 -> 0.039230597 | G46: =D25 -> 0.0060328945 | H46: =H33/H32-1 -> -0.67073171
A47: =A46+1 -> 20 | B47: =E20 -> 0.053390325 | C47: =E21 -> 1.7515353 | D47: =E22 -> 0.17728484 | E47: =E23 -> 0.09360748 | F47: =E24 -> 0.069903793 | G47: =E25 -> 0.019927921 | H47: =H34/H33-1 -> 2.4444444
...

Sheet SOCF
G1: Year | H1: FY21
A2: Year | B2: CFO | C2: CFI | D2: CFF | E2: Net Change
A3: FY17 | G3: CFO | H3: CFI | I3: CFF
A4: FY18
A5: FY19
A6: FY20
A7: FY21
A8: FY22
A9: FY23
A10: FY24
A11: FY25

Sheet Dashboard
